<?xml version="1.0"?>
<robot xmlns:xacro="http://ros.org/wiki/xacro">
  <xacro:include filename="$(find abb_resources)/urdf/common_materials.xacro"/>

  <xacro:macro name="abb_irb120_3_60" params="prefix">
    <!-- link list -->
    <link name="${prefix}base_link">
      <inertial>
        <mass value="${0.006181 * 25 / 0.00912}"/>
        <origin xyz="-0.041614 0.000184 0.079639"/>
        <inertia ixx="2.461236e-2" ixy="1.712983e-5" ixz="-1.226808e-4" iyy="4.855052e-2" iyz="2.222764e-5" izz="4.663803e-2"/>
      </inertial>
      <collision name="collision">
        <geometry>
          <mesh filename="package://abb_irb120_support/meshes/irb120_3_60/collision/base_link.stl"/>
        </geometry>
      </collision>
      <visual name="visual">
        <geometry>
          <mesh filename="package://abb_irb120_support/meshes/irb120_3_60/visual/base_link.dae"/>
        </geometry>
        <xacro:material_abb_yellow />
      </visual>
    </link>
    <link name="${prefix}link_1">
      <inertial>
        <mass value="${0.003061 * 25 / 0.00912}"/>
        <origin xyz="0.000099 -0.000113 -0.051699"/>
        <inertia ixx="1.416505e-2" ixy="1.357926e-5" ixz="2.089039e-5" iyy="1.434604e-2" iyz="-1.885864e-5" izz="1.042534e-2"/>
      </inertial>
      <collision name="collision">
        <geometry>
          <mesh filename="package://abb_irb120_support/meshes/irb120_3_60/collision/link_1.stl"/>
        </geometry>
      </collision>
      <visual name="visual">
        <geometry>
          <mesh filename="package://abb_irb120_support/meshes/irb120_3_60/visual/link_1.dae"/>
        </geometry>
        <xacro:material_abb_yellow />
      </visual>
    </link>
    <link name="${prefix}link_2">
      <inertial>
        <mass value="${0.003899 * 25 / 0.00912}"/>
        <origin xyz="0.000770 -0.002098 0.101320"/>
        <inertia ixx="6.007194e-2" ixy="-1.124530e-5" ixz="-5.731156e-5" iyy="4.138268e-2" iyz="4.955519e-5" izz="2.587382e-2"/>
      </inertial>
      <collision name="collision">
        <geometry>
          <mesh filename="package://abb_irb120_support/meshes/irb120_3_60/collision/link_2.stl"/>
        </geometry>
      </collision>
      <visual name="visual">
        <geometry>
          <mesh filename="package://abb_irb120_support/meshes/irb120_3_60/visual/link_2.dae"/>
        </geometry>
        <xacro:material_abb_yellow />
      </visual>
    </link>
    <link name="${prefix}link_3">
      <inertial>
        <mass value="${0.002939 * 25 / 0.00912}"/>
        <origin xyz="0.022817 0.001065 0.057957"/>
        <inertia ixx="8.319430e-3" ixy="7.957514e-5" ixz="-1.424078e-3" iyy="1.666783e-2" iyz="1.805283e-4" izz="1.267593e-2"/>
      </inertial>
      <collision name="collision">
        <geometry>
          <mesh filename="package://abb_irb120_support/meshes/irb120_3_60/collision/link_3.stl"/>
        </geometry>
      </collision>
      <visual name="visual">
        <geometry>
          <mesh filename="package://abb_irb120_support/meshes/irb120_3_60/visual/link_3.dae"/>
        </geometry>
        <xacro:material_abb_yellow />
      </visual>
    </link>
    <link name="${prefix}link_4">
      <inertial>
        <mass value="${0.001324 * 25 / 0.00912}"/>
        <origin xyz="0.224540 0.000239 0.000433"/>
        <inertia ixx="2.833033e-3" ixy="1.698253e-5" ixz="1.770183e-5" iyy="3.991053e-3" iyz="-1.404654e-5" izz="5.226945e-3"/>
      </inertial>
      <collision name="collision">
        <geometry>
          <mesh filename="package://abb_irb120_support/meshes/irb120_3_60/collision/link_4.stl"/>
        </geometry>
      </collision>
      <visual name="visual">
        <geometry>
          <mesh filename="package://abb_irb120_support/meshes/irb120_3_60/visual/link_4.dae"/>
        </geometry>
        <xacro:material_abb_yellow />
      </visual>
    </link>
    <link name="${prefix}link_5">
      <inertial>
        <mass value="${0.000548 * 25 / 0.00912}"/>
        <origin xyz="-0.000811 0.000034 0.000067"/>
        <inertia ixx="4.039701e-4" ixy="-1.305350e-6" ixz="-8.828193e-7" iyy="8.986250e-4" iyz="1.467132e-8" izz="8.222431e-4"/>
      </inertial>
      <collision name="collision">
        <geometry>
          <mesh filename="package://abb_irb120_support/meshes/irb120_3_60/collision/link_5.stl"/>
        </geometry>
      </collision>
      <visual name="visual">
        <geometry>
          <mesh filename="package://abb_irb120_support/meshes/irb120_3_60/visual/link_5.dae"/>
        </geometry>
        <xacro:material_abb_yellow />
      </visual>
    </link>
    <link name="${prefix}link_6">
      <inertial>
        <mass value="${0.000014 * 25 / 0.00912}"/>
        <origin xyz="-0.007054 -0.000169 0.000002"/>
        <inertia ixx="0.0001" ixy="0" ixz="0" iyy="0.0001" iyz="0" izz="0.0001"/>
      </inertial>
      <collision name="collision">
        <geometry>
          <mesh filename="package://abb_irb120_support/meshes/irb120_3_60/collision/link_6.stl"/>
        </geometry>
      </collision>
      <visual name="visual">
        <geometry>
          <mesh filename="package://abb_irb120_support/meshes/irb120_3_60/visual/link_6.dae"/>
        </geometry>
        <xacro:material_abb_yellow />
      </visual>
    </link>
    <!-- end of link list -->

    <!-- joint list -->
    <joint type="revolute" name="${prefix}joint_1">
      <origin xyz="0 0 0.290" rpy="0 0 0"/>
      <axis xyz="0 0 1"/>
      <parent link="${prefix}base_link"/>
      <child link="${prefix}link_1"/>
      <limit effort="0" lower="${radians(-165)}" upper="${radians(165)}" velocity="${radians(250)}"/>
      <dynamics damping="0.0" friction="0.0"/>
    </joint>
    <joint type="revolute" name="${prefix}joint_2">
      <origin xyz="0 0 0" rpy="0 0 0"/>
      <axis xyz="0 1 0"/>
      <parent link="${prefix}link_1"/>
      <child link="${prefix}link_2"/>
      <limit effort="0" lower="${radians(-110)}" upper="${radians(110)}" velocity="${radians(250)}"/>
      <dynamics damping="0.0" friction="0.0"/>
    </joint>
    <joint type="revolute" name="${prefix}joint_3">
      <origin xyz="0 0 0.270" rpy="0 0 0"/>
      <axis xyz="0 1 0"/>
      <parent link="${prefix}link_2"/>
      <child link="${prefix}link_3"/>
      <limit effort="0" lower="${radians(-110)}" upper="${radians(70)}" velocity="${radians(250)}"/>
      <dynamics damping="0.0" friction="0.0"/>
    </joint>
    <joint type="revolute" name="${prefix}joint_4">
      <origin xyz="0 0 0.070" rpy="0 0 0"/>
      <axis xyz="1 0 0"/>
      <parent link="${prefix}link_3"/>
      <child link="${prefix}link_4"/>
      <limit effort="0" lower="${radians(-160)}" upper="${radians(160)}" velocity="${radians(320)}"/>
      <dynamics damping="0.0" friction="0.0"/>
    </joint>
    <joint type="revolute" name="${prefix}joint_5">
      <origin xyz="0.302 0 0" rpy="0 0 0"/>
      <axis xyz="0 1 0"/>
      <parent link="${prefix}link_4"/>
      <child link="${prefix}link_5"/>
      <limit effort="0" lower="${radians(-120)}" upper="${radians(120)}" velocity="${radians(320)}"/>
      <dynamics damping="0.0" friction="0.0"/>
    </joint>
    <joint type="revolute" name="${prefix}joint_6">
      <origin xyz="0.072 0 0" rpy="0 0 0"/>
      <axis xyz="1 0 0"/>
      <parent link="${prefix}link_5"/>
      <child link="${prefix}link_6"/>
      <limit effort="0" lower="${radians(-400)}" upper="${radians(400)}" velocity="${radians(420)}"/>
      <dynamics damping="0.0" friction="0.0"/>
    </joint>
    <!-- end of joint list -->

    <!-- base frame-->
    <link name="${prefix}base" />
    <joint name="${prefix}base_link-base" type="fixed">
      <origin xyz="0 0 0" rpy="0 0 0"/>
      <parent link="${prefix}base_link"/>
      <child link="${prefix}base"/>
    </joint>

    <!-- flange frame -->
    <link name="${prefix}flange"/>
    <joint type="fixed" name="${prefix}joint_6-flange">
      <origin xyz="0 0 0" rpy="0 0 0"/>
      <parent link="${prefix}link_6"/>
      <child link="${prefix}flange"/>
    </joint>

    <!-- tool0 -->
    <link name="${prefix}tool0" />
    <joint name="${prefix}link_6-tool0" type="fixed">
      <origin xyz="0 0 0" rpy="0 ${radians(90)} 0" />
      <parent link="${prefix}flange" />
      <child link="${prefix}tool0" />
    </joint>
  </xacro:macro>
</robot>
